Workbook

Sheet Cover Sheet 
B9: Clearinghouse: ESB Funding and Financing Opportunities
B11: Author: World Resources Institute
B12: Date of Data Extract: 01/11/2024
B15: Purpose: Support school districts in their search for ESB funding and financing
B16: Navigation: The public version of the Clearinghouse Excel Workbook contains the following spreadsheet tabs
B17: Cover Sheet provides introduction and context for the work (this tab)
B18: Clearinghouse contains the program information that has been collected as of the date specified on the Cover Sheet
B19: Definitions & Lists defines each variable collected and details data type (either a list of options or open-ended)
B20: Data Sources: Several resources were referenced to identify funding opportunities, but all information included here was drawn directly from publicly-available sources. Reference files included:
B21: Alternative Fuels Data Center (AFDC)
B22: Atlas EV Hub
B23: U.S. Department of Transportation EV Federal Funding and Financing Programs
... B29: This is a dynamic document and WRI welcomes any feedback or updates from users. Please send any notes to Michelle Levinson (michelle.levinson@wri.org).

Sheet Definitions & Lists
A1: Column Header | B1: Priority | C1: Name | D1: Category | E1: Type | F1: Funder Type | G1: Geography | H1: Maximum Allowance | I1: Unit of Max Allowance | J1: Match | K1: Eligible Sectors/Types | L1: EJ Approach | M1: EJ Criteria | N1: Scrappage | O1: Applicable Technologies | P1: Application Status | Q1: Notes | R1: Application Website | S1: Source/Reference | T1: Source/Reference (2) | U1: Source/Reference (3)
A2: Definition | B2: Order in which schools should conduct their funding search, where A - Programs that are a best fit for ESBs B - Programs not specific to ESBs, such as those focused on technologies, economic development & clean energy C - Programs that are dormant, where status is unknown, or information on how to access is unknown | C2: Name of the program | D2: Nature of assistance provided | E2: Specific form of assistance provided | F2: Type of organization or institution providing assistance | G2: Geographic area to which program applies. Note that users should be expansive in selecting the broadest set of geographies that are pertinent | H2: Maximum amount applicants can access through program | I2: Unit by which potential maximum amount awarded is measured | J2: Minimum cost-sharing percentage. Unless "N/A" is selected, applicants will need to cover some of the expenses but these may not be specified | K2: Project purpose or applicant type eligible for assistance | L2: Characterization of environmental justice approach in the application process, describing potential benefits/advantages for applicants who meet the EJ Criteria. Some programs may apply a combination of approaches, or a highly tailored approach not captured here. | M2: Criteria through which environmental justice approach is applied. Where no approach is employed, "n/a" is selected | N2: If program requires scrappage of an older polluting bus, and if so the nature of this requirement | O2: Types of expenses that assistance can be applied towards | P2: Nature of open period for program applications | Q2: Any other program details noted by data collection team | R2: Link where general information on program can be found | S2: Other source or reference materials, as available | T2: Other source or reference materials, as available | U2: Other source or reference materials, as available
B3: A | C3: (open ended) | D3: Funding | E3: Grant | F3: Federal | G3: Federal - competitive | H3: ($ per unit) | I3: per bus | J3: N/A | K3: School Buses only | L3: none | M3: Pollution burden | N3: Required | O3: Bus (&/or Battery) | P3: Rolling | Q3: (open ended) | R3: (open ended) | S3: (open ended) | T3: (open ended) | U3: (open ended)
B4: B | D4: Financing | E4: Rebate | F4: Utility | G4: Tribal Government or Indigenous Communities | H4: (% up to max) | I4: incremental cost | J4: (if yes) % or other amount (open-ended) | K4: MDHV vehicles only | L4: exclusive to | M4: Race/Ethinicity/Tribe | N4: Not required | O4: Charger | P4: Annual Window
B5: C | D5: Other | E5: Discount/point of sale coupon or voucher | F5: State | G5: AL | H5: Varies | I5: per charger | J5: (if yes, unspecified) some amount | K5: Any public fleet vehicle | L5: prioritization | M5: Income | O5: Charger & infrastructure | P5: Unknown
E6: Incentive | F6: VW Settlement | G6: AK | H6: N/A | I6: per port | K6: Any fleet vehicles | L6: extra funds | M6: All | O6: Bus & Charger
E7: Tax Credit | F7: City | G7: AZ | I7: per charging session | K7: EVs | M7: Pollution + Race/Ethinicity/Tribe | O7: Infrastructure
E8: Technical Assistance | F8: County | G8: AR | I8: per applicant | K8: Other | M8: Income + Race/Ethinicity/Tribe | O8: Workforce Training
E9: Equipment | F9: Regional jurisdiction | G9: CA | I9: per district | K9: Resilience investments or Infrastructure | M9: Pollution + Income | O9: Maintenance Cost
E10: Sales/use tax exemption | F10: Philanthropic | G10: CO | I10: per site | K10: Economic development investments | M10: n/a | O10: Anything
E11: Loan | F11: Commercial bank | G11: CT | I11: per project | K11: Disaster recovery investments | O11: Other
E12: Rate | F12: Venture investors | G12: DE | I12: per kwh | K12: Energy | O12: New Bus or Repower Bus
E13: Bill Credit | F13: Green/clean energy bank | G13: FL | I13: per gallon | K13: Technology innovation | O13: Repower Bus & Charger
E14: Law | G14: GA | I14: per month
E15: Penalty/disincentive | G15: HI | I15: per year
E16: Cost allowance | G16: ID | I16: per event
G17: IL | I17: N/A
G18: IN
G19: IA
G20: KS
G21: KY
G22: LA
G23: ME
G24: MD
G25: MA
G26: MI
G27: MN
G28: MS
G29: MO
... G63: Federal

Sheet Clearinghouse Official
A1: Priority | B1: Name | C1: Category | D1: Type | E1: Funder Type | F1: Geography | G1: Maximum Allowance | H1: Unit of Max Allowance | I1: Minimum Match Requirement | J1: Eligible Sectors/Types | K1: EJ Approach | L1: EJ Criteria | M1: Scrappage | N1: Applicable Technologies | O1: Application Status | P1: Notes | Q1: Program Website | R1: Source/Reference | S1: Source/Reference (2) | T1: Source/Reference (3)
A2: C | B2: Electric Vehicle Supply Equipment (EVSE) Funding Authorization | C2: Other | D2: Law | E2: State | F2: CO | G2: N/A | H2: N/A | I2: N/A | J2: EVs | K2: prioritization | L2: All | M2: Not required | N2: Bus & Charger | O2: Rolling | P2: Law provides new funding available for sustainable transportation. It creates three new transportation electrification enterprises: the Clean Transit Enterprise housed in the Colorado Department of Transportation (CDOT), the Clean Fleet Enterprise housed in the Colorado Department of Public Health and Environment (CDPHE), and the Community Access Enterprise housed in the Colorado Energy Office (CEO). | Q2: https://energyoffice.colorado.gov/about-us/boards-commissions/community-access-enterprise | R2: https://leg.colorado.gov/bills/sb21-260 | S2: Alternative Fuels Data Center: Electric Vehicle (EV) Charging Stations Funding Authorization (energy.gov)
A3: C | B3: Small-Scale Local Energy Loan Program | C3: Financing | D3: Loan | E3: State | F3: OR | G3: N/A | H3: N/A | I3: N/A | J3: Energy | K3: none | L3: n/a | M3: Not required | N3: Anything | O3: Unknown | P3: SELP is not currently accepting new loan applications. | Q3: https://www.oregon.gov/energy/incentives/pages/energy-loan-program.aspx
A4: B | B4: Community Project Funding | C4: Funding | D4: Grant | E4: Federal | F4: Federal | G4: N/A | H4: N/A | I4: N/A | J4: Other | K4: none | L4: n/a | M4: Not required | N4: Anything | O4: Annual Window | Q4: https://appropriations.house.gov/fiscal-year-2024-member-request-guidance | R4: Fact Sheet on Reforms 2023.pdf (house.gov) | S4: https://appropriations.house.gov/sites/democrats.appropriations.house.gov/files/Ag%20Request%20Guidance.pdf
A5: B | B5: Indian Energy Program | C5: Funding | D5: Grant | E5: Federal | F5: Tribal Government or Indigenous Communities | G5: N/A | H5: N/A | I5: N/A | J5: Other | K5: exclusive to | L5: Race/Ethinicity/Tribe | M5: Not required | N5: Anything | O5: Rolling | P5: No specific funding provided. Information of current funding opportunities from federal agencies and other entities for tribal energy projects development and deployment. | Q5: https://www.energy.gov/indianenergy/office-indian-energy-policy-and-programs | R5: Current Funding Opportunities | Department of Energy
A6: B | B6: Congestion Mitigation and Air Quality Improvement Program | C6: Funding | D6: Rebate | E6: Federal | F6: Federal - state admin | G6: N/A | H6: N/A | I6: N/A | J6: Any public fleet vehicle | K6: prioritization | L6: Pollution burden | M6: Not required | N6: Anything | O6: Annual Window | P6: CMAQ provides flexible funding to state and local governments for transportation projects. Schools should reach out to local and state government for funding. | Q6: https://www.law.cornell.edu/uscode/text/23/149 | R6: https://www.fhwa.dot.gov/bipartisan-infrastructure-law/cmaq.cfm | S6: CMAQ-Workbook-2022.pdf (ewgateway.org)
A7: C | B7: Alternative Fuel Vehicle Research and Development Funding | C7: Funding | D7: Incentive | E7: State | F7: NY | G7: N/A | H7: N/A | I7: N/A | J7: Any fleet vehicles | K7: prioritization | L7: Pollution + Income | M7: Not required | N7: Anything | O7: Unknown | P7: Broad category of funding for R&D; individual RFPs/funding opps are updated on the website under this umbrella with more specifics | Q7: https://www.nyserda.ny.gov/All-Programs/Clean-Transportation-Program
A8: A | B8: Alternative Fuels Incentive Grant Program | C8: Funding | D8: Rebate | E8: State | F8: PA | G8: 300000 | H8: incremental cost | I8: 0.5 | J8: Any fleet vehicles | K8: prioritization | L8: Income + Race/Ethinicity/Tribe | M8: Not required | N8: New Bus or Repower Bus | O8: Annual Window | P8: Program will reopen Spring 2024. It cannot be stacked with any VW funding. | Q8: https://www.dep.pa.gov/Citizens/GrantsLoansRebates/Alternative-Fuels-Incentive-Grant/Pages/default.aspx | R8: AFIG_Webinar_08162022.pptx (live.com)
A9: B | B9: SC Energy Efficiency Revolving Loan Program | C9: Financing | D9: Loan | E9: State | F9: SC | G9: 1000000 | H9: per applicant | I9: Yes, unspecified | J9: Energy | K9: none | L9: n/a | M9: Not required | N9: Anything | O9: Rolling | Q9: https://www.businessdevelopment.org/eerl.html | R9: https://www.businessdevelopment.org/eerl.html | S9: https://afdc.energy.gov/laws/11518
A10: A | B10: Government Alternative Fuel Vehicle (AFV) Incentive | C10: Funding | D10: Rebate | E10: Federal | F10: VA | G10: 10000 | H10: incremental cost | I10: Yes, unspecified | J10: Any public fleet vehicle | K10: prioritization | L10: Pollution burden | M10: Not required | N10: Bus (&/or Battery) | O10: Rolling | P10: Funding is currently available through September 30, 2024. Fleets that are interested in utilizing this Program for the purchase or conversion to new alternative fuel vehicles should first contact Alleyn Harned (540-568-8896) or Matt Wade (540-568-4051) with Virginia Clean Cities. | Q10: https://vacleancities.org/reports-2/cmaq-incentive-program/ | R10: https://vacleancities.org/wp-content/uploads/2023/12/CMAQ-Application-Package-Final-12_11_23.pdf | S10: https://afdc.energy.gov/laws/all?state=VA
A11: A | B11: Environmental Justice Small Grant Program | C11: Funding | D11: Grant | E11: Federal | F11: Federal - competitive | G11: 100000 | H11: per applicant | I11: Yes, unspecified | J11: Economic development investments | K11: exclusive to | L11: Income + Race/Ethinicity/Tribe | M11: Not required | N11: Anything | O11: Annual Window | P11: Restricted to federally recognized tribal goverments | Q11: https://www.epa.gov/environmentaljustice/environmental-justice-small-grants-program#Eligibility
A12: B | B12: Energy/Mineral Impact Assistance Fund Grant | C12: Funding | D12: Grant | E12: State | F12: CO | G12: 1000000 | H12: per applicant | I12: 0.5 | J12: Economic development investments | K12: prioritization | L12: Pollution + Income | M12: Not required | N12: Anything | O12: Annual Window | P12: The Energy/Mineral Impact Assistance Fund Grant (EIAF) program assists political subdivisions that are socially and/or economically impacted by the development, processing, or energy conversion of minerals and mineral fuels. | Q12: https://cdola.colorado.gov/funding-programs/energy/mineral-impact-assistance-fund-grant-eiaf | R12: https://cdola.colorado.gov/funding-programs/energy/mineral-impact-assistance-fund-grant-eiaf | S12: https://drive.google.com/file/d/16LBF9sUL6nx3cv1K0B73lTMgH1teAT9w/view
A13: A | B13: South Carolina Mini-Grants | C13: Funding | D13: Grant | E13: Federal | F13: SC | G13: 10000 | H13: per applicant | I13: Yes, unspecified | J13: Energy | K13: none | L13: n/a | M13: Not required | N13: Anything | O13: Annual Window | P13: No mentioned of EJ approach. | Q13: https://energy.sc.gov/programs/funding/mini-grant-program | S13: http://energy.sc.gov/files/view/Mini%20Grant%20Overview_2021_LM.pdf | T13: Alternative Fuels Data Center: Alternative Fuel Project Grants (energy.gov)
A14: C | B14: Indigenous Communities Program (American Rescue Plan) | C14: Funding | D14: Grant | E14: Federal | F14: Tribal Government or Indigenous Communities | G14: 5000000 | H14: per applicant | I14: Yes, unspecified | J14: Economic development investments | K14: exclusive to | L14: Race/Ethinicity/Tribe | M14: Not required | N14: Anything | O14: Unknown | P14: Last round closed April 2022. Funds have to be awarded by September 30, 2022. | Q14: https://eda.gov/arpa/indigenous/ | R14: Indigenous-Communities-webinar-slides.pdf (eda.gov) | S14: American Rescue Plan Indigenous Communities – Frequently Asked Questions - American Rescue Plan | U.S. Economic Development Administration (eda.gov)
A15: B | B15: State Economic & Infrastructure Development Investment Program | C15: Funding | D15: Grant | E15: Federal | F15: Regional - state admin | G15: 100000000 | H15: per applicant | I15: Yes, unspecified | J15: Economic development investments | K15: extra funds | L15: Income | M15: Not required | N15: Anything | O15: Annual Window | P15: Letters of interest by April 2023 | Q15: https://www.nbrc.gov/content/Catalyst | R15: NBRC Catalyst Program Overview.pdf
A16: B | B16: Inflation Reduction Act Community Change Grants Program | C16: Funding | D16: Grant | E16: Federal | F16: Federal - competitive | G16: 20000000 | H16: per applicant | I16: Yes, unspecified | J16: Resilience investments or Infrastructure | K16: exclusive to | L16: All | M16: Not required | N16: Anything | O16: Rolling | P16: Deadline November 2024 | Q16: https://www.epa.gov/inflation-reduction-act/inflation-reduction-act-community-change-grants-program | R16: https://www.epa.gov/system/files/documents/2023-12/epa-ira-oejecr-ccg-nofo-final-2023-12-20.pdf
A17: B | B17: State Energy Program | C17: Funding | D17: Grant | E17: Federal | F17: Federal - state admin | G17: Varies | H17: per applicant | I17: Yes, unspecified | J17: Energy | K17: prioritization | L17: All | M17: Not required | N17: Anything | O17: Annual Window | P17: Grant awarded only to states. | Q17: https://www.energy.gov/eere/wipo/state-energy-program-guidance | R17: SEP Program Notice 23-01 Program Year 2023 State Energy Program Formula Grant Application Instructions.pdf
A18: A | B18: Clean Air Grant | C18: Funding | D18: Grant | E18: VW Settlement | F18: NV | G18: 1 | H18: incremental cost | I18: Yes, unspecified | J18: MDHV vehicles only | K18: prioritization | L18: All | M18: Required | N18: New Bus or Repower Bus | O18: Annual Window | P18: Most recent round 2022. Upcoming funding expected | Q18: NV Clean Air Grant | R18: 2021 Application Form | S18: DEMF 2021 Competitive Application Webinar (nv.gov)
A19: C | B19: Clean Fuel Advanced Technology Project Grant Funding | C19: Funding | D19: Grant | E19: Federal | F19: NC | G19: 300000 | H19: per applicant | I19: 0.24 | J19: Other | K19: none | L19: n/a | M19: Not required | N19: Anything | O19: Unknown | P19: Last Round closed Sept. 2022. While there's no mentioned of EJ approach, the grant has to be implemented in pre-selected counties. | Q19: https://nccleantech.ncsu.edu/our-work/center-projects/cfat-project-request-for-proposals-information/ | R19: https://drive.google.com/file/d/1wnRhVO4Xd8ZsOnnVeZ0r2B9TAD7jdsHo/view | S19: https://afdc.energy.gov/fuels/laws/NG?state=NC
A20: B | B20: Community Facilities Direct Loan and Grant Program | C20: Financing | D20: Loan | E20: Federal | F20: Federal - competitive | G20: N/A | H20: N/A | I20: N/A | J20: Other | K20: extra funds | L20: Income | M20: Not required | N20: Anything | O20: Rolling | P20: Focused on rural communities. Applicants must show proof they cannot get a commercial loan. | Q20: https://www.rd.usda.gov/programs-services/community-facilities/community-facilities-direct-loan-grant-program#overview | R20: Community Facilities Direct Loan Program (usda.gov)
A21: B | B21: Congressionally Directed Spending | C21: Funding | D21: Grant | E21: Federal | F21: Federal | G21: N/A | H21: N/A | I21: N/A | J21: Other | K21: none | L21: n/a | M21: Not required | N21: Anything | O21: Annual Window | P21: Schools are encourage to contact their senate representative. | Q21: https://www.appropriations.senate.gov/congressionally-directed-spending-requests
A22: C | B22: Alternative Fuel Vehicles and Infrastructure Grant Program (ALT Fuels Colorado) | C22: Funding | D22: Rebate | E22: VW Settlement | F22: CO | G22: 1.17 | H22: incremental cost | I22: Yes, unspecified | J22: MDHV vehicles only | K22: none | L22: n/a | M22: Required | N22: Bus (&/or Battery) | O22: Unknown | P22: Most recent round was 2021. As of January 2022, all funding allocated has been distributed. Future funding opportunities will be offered & managed by the Colorado Department of Public Health & Environment (CDPHE) Clean Fleet Enterprise. No information on future programs. | Q22: https://raqc.org/program/alt-fuels-colorado/#:~:text=The%20Program%20ALT%20Fuels%20Colorado%20removes%20barriers%20to,AFVs%20by%20providing%20incentives%20to%20offset%20incremental%20costs. | R22: AFC Program Guide.pdf (egnyte.com) | S22: https://afdc.energy.gov/laws/11489
A23: A | B23: ConserFund | C23: Financing | D23: Loan | E23: State | F23: SC | G23: 500000 | H23: per district | I23: Yes, unspecified | J23: Energy | K23: none | L23: n/a | M23: Not required | N23: Anything | O23: Rolling | P23: 1.5% interest rate | Q23: https://energy.sc.gov/programs/funding/loans/conserfund | R23: http://www.energy.sc.gov/incentives/conserfund | S23: http://www.energy.sc.gov/files/CF%20FAQ%27s%20-%20Basics%20-10.07.2020_0.pdf | T23: https://afdc.energy.gov/laws/11517
A24: C | B24: Clean Fuels Incentive Program | C24: Funding | D24: Grant | E24: State | F24: MD | G24: 150000 | H24: incremental cost | I24: Yes, unspecified | J24: Any fleet vehicles | K24: prioritization | L24: All | M24: Not required | N24: Bus (&/or Battery) | O24: Unknown | P24: Vehicles associated with the replacement or retirement of existing gas/diesel vehicles will be viewed more favorably during the application process. Applications closed 2022. | Q24: https://energy.maryland.gov/transportation/Pages/Clean-Fuels-Incentive-Program.aspx | R24: FY23 CFIP FOA Final.docx (maryland.gov)
A25: A | B25: AFV Mechanic Training Program | C25: Funding | D25: Grant | E25: State | F25: CA | G25: 15000 | H25: per applicant | I25: Yes, unspecified | J25: Any fleet vehicles | K25: none | L25: n/a | M25: Not required | N25: Workforce Training | O25: Rolling | P25: This is strictly a training program. | Q25: http://valleyair.org/grants/mechanictraining.htm | R25: Alt Fuel Mech Trng Guidelines Document Revised.PDF (valleyair.org)
A26: C | B26: Transportation Electrification Infrastructure Projects | C26: Other | D26: Law | E26: State | F26: IL | G26: N/A | H26: N/A | I26: N/A | J26: Any fleet vehicles | K26: prioritization | L26: Pollution burden | M26: Not required | N26: Bus (&/or Battery) | O26: Rolling | P26: Law that provides funding to the Environmental Protection Agency for grants for transportation electrification infrastructure projects; including, but not limited to grants for the purpose of encouraging electric vehicle charging infrastructure, prioritizing investments in medium and heavy-duty charging, and electrifying public transit, fleets, and school buses. | Q26: https://www.ilga.gov/legislation/publicacts/101/PDF/101-0029.pdf | R26: Alternative Fuels Data Center: Transportation Electrification Infrastructure Projects (energy.gov)
A27: A | B27: Literary Funds Loans | C27: Financing | D27: Loan | E27: State | F27: VA | G27: 25000000 | H27: per applicant | I27: Yes, unspecified | J27: School Buses only | K27: none | L27: n/a | M27: Not required | N27: Anything | O27: Annual Window | P27: Most recent round closed Nov 16, 2023 (opened Sept 21, 2023 - small window). Pursuant to the appropriation act, the Department of Education shall conduct an annual open enrollment process for loan applications. | Q27: https://www.doe.virginia.gov/programs-services/school-operations-support-services/facility-construction-maintenance/literary-fund-loans | R27: https://lis.virginia.gov/cgi-bin/legp604.exe?071+ful+CHAP0121&071+ful+CHAP0121 | S27: https://law.lis.virginia.gov/vacode/title22.1/chapter10/section22.1-146/ | T27: Superintendent’s Memo #273-22 (virginia.gov)
A28: C | B28: New York State’s Beneficiary Mitigation Plan | C28: Funding | D28: Incentive | E28: VW Settlement | F28: NY | G28: N/A | H28: N/A | I28: N/A | J28: MDHV vehicles only | K28: prioritization | L28: Pollution burden | M28: Not required | N28: New Bus or Repower Bus | O28: Unknown | P28: It seems all VW funds were awarded: At this time, there are no plans to reopen the application process. | Q28: https://www.dec.ny.gov/chemical/109784.html
A29: C | B29: Funds for School District Alternative Fuel Use | C29: Other | D29: Law | E29: State | F29: NV | G29: N/A | H29: N/A | I29: N/A | J29: School Buses only | K29: none | L29: n/a | M29: Not required | N29: Bus & Charger | O29: Rolling | P29: Violations of air pollution control laws will lead to fines that school districts receive, local air pollution control board approves what $ can be spent on; repowers specifically named | Q29: https://www.leg.state.nv.us/NRS/NRS-445B.html#NRS445BSec500 | R29: https://afdc.energy.gov/fuels/laws/NG?state=NV#:~:text=%28Reference%20Nevada%20Revised%20Statutes484A.463%29%20Funds%20for%20School%20District,county%20school%20district%20fund%20where%20the%20violation%20occurred.
A30: A | B30: Clean Diesel Grant Program | C30: Funding | D30: Rebate | E30: VW Settlement | F30: SD | G30: 0.45 | H30: per applicant | I30: 0.55 | J30: MDHV vehicles only | K30: none | L30: n/a | M30: Required | N30: Bus & Charger | O30: Annual Window | P30: Closed Dec 8 2023. Clean Diesel Grant Program utilizes funding from VW and DERA to replace diesel buses. | Q30: https://danr.sd.gov/Environment/AirQuality/CleanDieselProgram/default.aspx | R30: https://danr.sd.gov/Environment/AirQuality/CleanDieselProgram/docs/R14App.pdf | S30: https://afdc.energy.gov/laws/12401
A31: A | B31: Diesel Emission Reduction Project Funding (DERA) | C31: Funding | D31: Grant | E31: Federal | F31: IA | G31: 0.45 | H31: per applicant | I31: 0.55 | J31: MDHV vehicles only | K31: prioritization | L31: Pollution burden | M31: Required | N31: Bus (&/or Battery) | O31: Annual Window | P31: Closed Oct 2023. The replaced bus must be scrapped or permanently disabled within ninety (90) days of being replaced. | Q31: https://iowadot.gov/dera/Application-Process | R31: https://iowadot.gov/dera/pdfs/DERA-Grant-Program-Information-Guide-2023.pdf | S31: https://afdc.energy.gov/laws/12125
A32: A | B32: North Carolina Mobile Source Emissions Reduction Grant | C32: Funding | D32: Grant | E32: State | F32: NC | G32: 0.45 | H32: per applicant | I32: 0.65 | J32: Any fleet vehicles | K32: prioritization | L32: Pollution + Income | M32: Required | N32: New Bus or Repower Bus | O32: Annual Window | P32: Application open November 2023 and close Feb 2024. EJ Criteria varies. Also includes minority-owned, etc. depending on which part of DERA funding applicant is applying for | Q32: https://deq.nc.gov/about/divisions/air-quality/motor-vehicles-and-air-quality/mobile-sources-emissions-reductions-grant | R32: open (nc.gov)
A33: A | B33: Vermont Diesel Emissions Reduction Financial Assistance (DERA) | C33: Funding | D33: Grant | E33: Federal | F33: VT | G33: 0.45 | H33: per applicant | I33: 0.55 | J33: MDHV vehicles only | K33: prioritization | L33: Pollution + Income | M33: Required | N33: New Bus or Repower Bus | O33: Annual Window | P33: Most recent round closed Dec. 2023. Application done through Vermont Business Assistance Network | Q33: https://dec.vermont.gov/air-quality/mobile-sources/diesel-emissions/vt-diesel-grant | R33: 2021-2022 Diesel Emissions Reduction Act (DERA) State Grants Program Guide (EPA-420-B-22-023, April 2022) (vermont.gov) | S33: https://afdc.energy.gov/laws/12003
A34: C | B34: Alternative Fuel and Alternative Fuel Vehicle (AFV) Fund | C34: Other | D34: Law | E34: State | F34: NC | G34: N/A | H34: N/A | I34: N/A | J34: Any public fleet vehicle | K34: none | L34: n/a | M34: Not required | N34: Bus (&/or Battery) | O34: Rolling | P34: The North Carolina State Energy Office administers the Energy Policy Act (EPAct) Credit Banking and Selling Program, which enables the state to generate funds from the sale of EPAct 1992 credits. The funds that EPAct credit sales generate are deposited into the Alternative Fuel Revolving Fund (Fund) for state agencies to offset the incremental costs of purchasing biofuel or electric vehicles. | Q34: https://law.justia.com/codes/north-carolina/2012/chapter-143/article-3/section-143-58.5/ | R34: https://afdc.energy.gov/fuels/laws/NG?state=NC
A35: C | B35: Vehicle Emissions Reduction and Electric Vehicle Supply Equipment (EVSE) Project Funding | C35: Funding | D35: Grant | E35: VW Settlement | F35: LA | G35: N/A | H35: N/A | I35: N/A | J35: Any fleet vehicles | K35: prioritization | L35: Pollution burden | M35: Required | N35: Bus (&/or Battery) | O35: Unknown | P35: It seems all VW funds were awarded (2022): At this time, there are no plans to reopen the application process. | Q35: https://deq.louisiana.gov/page/louisiana-volkswagen-environmental-mitigation-trust
A36: C | B36: Diesel Emissions Reduction Act Tribal and Insular Areas Grants (DERA) | C36: Funding | D36: Grant | E36: Federal | F36: Tribal Government or Indigenous Communities | G36: 800000 | H36: per applicant | I36: Yes, unspecified | J36: Any fleet vehicles | K36: prioritization | L36: Pollution + Income | M36: Required | N36: New Bus or Repower Bus | O36: Unknown | P36: Most recent round closed Oct. 2022 | Q36: https://www.epa.gov/dera/tribal-insulararea
A37: A | B37: Plug-In Electric Vehicle (PEV) Time-Of-Use (TOU) - NV Energy | C37: Other | D37: Rate | E37: Utility | F37: NV | G37: Varies | H37: per applicant | I37: N/A | J37: EVs | K37: none | L37: n/a | M37: Not required | N37: Maintenance Cost | O37: Rolling | P37: Must participate for 1 year, can switch to regular cost if not satisfied after 1 year; TOU for off-peak charging | Q37: https://www.nvenergy.com/account-services/energy-pricing-plans/time-of-use/sign-up-residential | R37: https://www.nvenergy.com/account-services/energy-pricing-plans/electric-vehicle
A38: C | B38: Medium- and Heavy-Duty Grant Program | C38: Funding | D38: Grant | E38: VW Settlement | F38: IN | G38: 0.75 | H38: per applicant | I38: Yes, unspecified | J38: Any public fleet vehicle | K38: prioritization | L38: Pollution burden | M38: Required | N38: Bus (&/or Battery) | O38: Unknown | P38: Most recent round was 2022 | Q38: https://www.in.gov/idem/airquality/volkswagen-mitigation-trust/ | R38: https://afdc.energy.gov/laws/12180 | S38: https://www.in.gov/idem/airquality/files/vw_trust_decree_apndx_d2.pdf
A39: A | B39: Diesel Emissions Reduction Act National Grants (DERA) | C39: Funding | D39: Grant | E39: Federal | F39: Federal - competitive | G39: Varies | H39: per applicant | I39: Yes, unspecified | J39: Any fleet vehicles | K39: prioritization | L39: Pollution + Income | M39: Required | N39: Bus (&/or Battery) | O39: Annual Window | P39: Application opened Aug 2023, closed Dec 1, 2023 | Q39: https://www.epa.gov/grants/2022-2023-diesel-emissions-reduction-act-dera-national-grants | R39: https://www.epa.gov/system/files/documents/2023-08/dera-national-program-nofo-fY22-fY23-final-8-1-23-v4.pdf
A40: A | B40: Georgia Converted Vehicle and EV Charger Tax Credits | C40: Funding | D40: Tax Credit | E40: State | F40: GA | G40: 2500 | H40: per bus | I40: 0.9 | J40: Any fleet vehicles | K40: none | L40: n/a | M40: Not required | N40: Repowered Bus & Charger | O40: Rolling | P40: Tax credit is still available for vehicles converted to alternative fuels. The LEV/ZEV and MDV/HDV tax credits were discontinued effective July 1, 2015. | Q40: https://epd.georgia.gov/forms-permits/air-protection-branch-forms-permits/clean-vehicle-tax-credits | R40: https://afdc.energy.gov/laws/13209
...

Sheet US States + Territories
A1: US STATE | B1: POSTAL ABBREVIATION | C1: STANDARD ABBREVIATION | F1: Territory/Commonwealth | G1: Postal Abbreviation | H1: Standard Abbreviation
A2: Alabama | B2: AL | C2: Ala. | F2: District of Columbia | G2: DC | H2: D.C.
A3: Alaska | B3: AK | C3: Alaska | F3: Guam | G3: GU | H3: Guam
A4: Arizona | B4: AZ | C4: Ariz. | F4: Marshall Islands | G4: MH | H4: M.I.
A5: Arkansas | B5: AR | C5: Ark. | F5: Northern Mariana Island | G5: MP | H5: CNMI
A6: California | B6: CA | C6: Calif. | F6: Puerto Rico | G6: PR | H6: P.R. or PUR
A7: Colorado | B7: CO | C7: Color. | F7: Virgin Islands | G7: VI | H7: V.I.
A8: Connecticut | B8: CT | C8: Conn.
A9: Delaware | B9: DE | C9: Del.
A10: Florida | B10: FL | C10: Fla.
A11: Georgia | B11: GA | C11: Ga.
A12: Hawaii | B12: HI | C12: Hawaii
A13: Idaho | B13: ID | C13: Idaho
A14: Illinois | B14: IL | C14: Ill.
A15: Indiana | B15: IN | C15: Ind.
A16: Iowa | B16: IA | C16: Iowa
A17: Kansas | B17: KS | C17: Kan.
A18: Kentucky | B18: KY | C18: Ky.
A19: Louisiana | B19: LA | C19: La.
... A51: Wyoming | B51: WY | C51: Wyo.

Sheet AVG Awards
B3: $ | C3: % | F3: $ | G3: % | J3: $ | K3: %
A4: Anything | B4: =AVERAGE($B$5:$B$6) -> #REF! | C4: =AVERAGE(C5:C6) -> #REF! | E4: Any fleet vehicles | F4: =AVERAGE($F$5,$F$6:$F$9,$F$10) -> #REF! | G4: =AVERAGE($G$6,$G$9) -> #REF! | I4: Any fleet vehicles | J4: =AVERAGE($J$5:$J$8,$J$10) -> #REF! | K4: =AVERAGE(K7:K9,K5) -> #REF! | N4: Anything | O4: =AVERAGE($J$23,$J$26,$J$50) -> #REF! | R4: City | S4: State | T4: Utility | U4: VW | V4: Federal | W4: AVERAGE TECH
A5: per applicant | B5: =AVERAGE('Clearinghouse Official'!G$10,'Clearinghouse Official'!G$11,'Clearinghouse Official'!G$12,'Clearinghouse Official'!G$13,'Clearinghouse Official'!G$14,'Clearinghouse Official'!G$15,'Clearinghouse Official'!G$16,'Clearinghouse Official'!#REF!,'Clearinghouse Official'!G$17,'Clearinghouse Official'!G$19,'Clearinghouse Official'!G$23) -> #REF! | C5: =AVERAGE('Clearinghouse Official'!$G$10,'Clearinghouse Official'!#REF!) -> #REF! | E5: incremental cost | F5: =AVERAGE('Clearinghouse Official'!$G$7:$G$8) -> 300000 | I5: Bus (&/or Battery) | J5: =AVERAGE('Clearinghouse Official'!$G$8,'Clearinghouse Official'!$G$24,'Clearinghouse Official'!$G$36,'Clearinghouse Official'!$G$39:$G$40,'Clearinghouse Official'!$G$8) -> 310500 | K5: =AVERAGE('Clearinghouse Official'!#REF!,'Clearinghouse Official'!#REF!,'Clearinghouse Official'!G$32) -> #REF! | N5: Bus (&/or Battery) | O5: =AVERAGE(J$5,J$14,J$27,J$33,J$39,J$46,J$51) -> #REF! | Q5: Anything | S5: =AVERAGE('Clearinghouse Official'!$G$9,'Clearinghouse Official'!$G$12,'Clearinghouse Official'!$G$23) -> 833333.33 | V5: =AVERAGE('Clearinghouse Official'!$G$11,'Clearinghouse Official'!$G$13:$G$16,'Clearinghouse Official'!$G$19) -> 20901667 | W5: =AVERAGE($S$5,$V$5) -> 10867500
A6: per district | B6: ='Clearinghouse Official'!$G$131 -> 1000000 | C6: ='Clearinghouse Official'!$G$123 -> 975000 | E6: per applicant | F6: =AVERAGE('Clearinghouse Official'!$G39:$G40,'Clearinghouse Official'!$G49,'Clearinghouse Official'!$G82,'Clearinghouse Official'!$G84:$G85,'Clearinghouse Official'!$G105,'Clearinghouse Official'!$G112,'Clearinghouse Official'!$G126,'Clearinghouse Official'!$G36,'Clearinghouse Official'!$G65,'Clearinghouse Official'!$G102,'Clearinghouse Official'!$G121) -> 140090.97 | G6: =AVERAGE('Clearinghouse Official'!G$32:G$32,'Clearinghouse Official'!G$53,'Clearinghouse Official'!#REF!,'Clearinghouse Official'!G$49,'Clearinghouse Official'!#REF!) -> #REF! | I6: Bus + Charger | J6: ='Clearinghouse Official'!$G$53 -> 5000 | N6: Bus + Charger | O6: =AVERAGE($J$6,$J$15,$J$28,$J$40,$J$47) -> 135000 | Q6: Bus (&/or Battery) | R6: ='Clearinghouse Official'!$G$89 -> 0.5 | S6: =AVERAGE('Clearinghouse Official'!$G$96:$G$101,'Clearinghouse Official'!$G$92,'Clearinghouse Official'!$G$90:$G$91,'Clearinghouse Official'!#REF!,'Clearinghouse Official'!$G$80,'Clearinghouse Official'!$G$48,'Clearinghouse Official'!$G$40:$G$41,'Clearinghouse Official'!$G$24,'Clearinghouse Official'!$G$8) -> #REF! | T6: =AVERAGE('Clearinghouse Official'!$G$87,'Clearinghouse Official'!#REF!,'Clearinghouse Official'!$G$37) -> #REF! | U6: =AVERAGE('Clearinghouse Official'!$G$38,'Clearinghouse Official'!$G$42,'Clearinghouse Official'!$G$44:$G$44,'Clearinghouse Official'!$G$47,'Clearinghouse Official'!$G$50:$G$50,'Clearinghouse Official'!$G$72,'Clearinghouse Official'!$G$74,'Clearinghouse Official'!$G$79,'Clearinghouse Official'!$G$86,'Clearinghouse Official'!$G$111,'Clearinghouse Official'!$G$123,'Clearinghouse Official'!$G$130) -> 312009.4 | V6: =AVERAGE('Clearinghouse Official'!$G$10,'Clearinghouse Official'!$G$36,'Clearinghouse Official'!$G$39,'Clearinghouse Official'!$G$43,'Clearinghouse Official'!$G$45,'Clearinghouse Official'!$G$93,'Clearinghouse Official'!#REF!) -> #REF! | W6: =AVERAGE($R$6:$V$6) -> #REF!
E7: per bus | F7: ='Clearinghouse Official'!#REF! -> #REF! | I7: Charger | J7: =AVERAGE('Clearinghouse Official'!$G$141,'Clearinghouse Official'!$G$138,'Clearinghouse Official'!$G$134,'Clearinghouse Official'!#REF!,'Clearinghouse Official'!#REF!,'Clearinghouse Official'!$G$121,'Clearinghouse Official'!$G$112,'Clearinghouse Official'!$G$105,'Clearinghouse Official'!$G$102,'Clearinghouse Official'!$G$84:$G$85,'Clearinghouse Official'!$G$82) -> #REF! | K7: ='Clearinghouse Official'!$G$65 -> 0.65 | N7: Charger | O7: =AVERAGE($J$7,$J$16,$J$35,$J$41) -> #REF! | Q7: Bus + Charger | S7: =AVERAGE('Clearinghouse Official'!$G49,'Clearinghouse Official'!$G66) -> #DIV/0! | T7: =AVERAGE('Clearinghouse Official'!$G$55,'Clearinghouse Official'!$G$53) -> 5000 | U7: =AVERAGE('Clearinghouse Official'!$G$104) -> 375000 | W7: =AVERAGE($S$7:$U$7) -> #DIV/0!
A8: Bus (&/or Battery) | B8: =AVERAGE(B10:B12,B9) -> #REF! | C8: =AVERAGE(C12,C10:C11,C9) -> #REF! | E8: per charger | F8: =AVERAGE('Clearinghouse Official'!G$134,'Clearinghouse Official'!G$141,'Clearinghouse Official'!#REF!,'Clearinghouse Official'!G$146,'Clearinghouse Official'!G$149:G$150,'Clearinghouse Official'!G$152:G$153,'Clearinghouse Official'!G$138) -> #REF! | I8: Charger + infrastructure | J8: =AVERAGE('Clearinghouse Official'!$G$180,'Clearinghouse Official'!$G$177,'Clearinghouse Official'!$G$161,'Clearinghouse Official'!$G$152:$G$153,'Clearinghouse Official'!$G$150,'Clearinghouse Official'!$G$149,'Clearinghouse Official'!$G$146,'Clearinghouse Official'!$G$167) -> 20655.556 | K8: ='Clearinghouse Official'!#REF! -> #REF! | N8: Charger + infrastructure | O8: =AVERAGE($J$8,$J$17,$J$29,$J$36,$J$42,$J$52) -> #REF! | Q8: Charger | R8: ='Clearinghouse Official'!$G$133 -> 10000 | S8: =AVERAGE('Clearinghouse Official'!$G$141,'Clearinghouse Official'!$G$137:$G$138,'Clearinghouse Official'!$G$121:$G$121,'Clearinghouse Official'!$G$112) -> 10900 | T8: =AVERAGE('Clearinghouse Official'!$G$56:$G$59,'Clearinghouse Official'!$G$61:$G$63,'Clearinghouse Official'!$G$66:$G$67,'Clearinghouse Official'!$G$82,'Clearinghouse Official'!$G$84:$G$85,'Clearinghouse Official'!$G$95,'Clearinghouse Official'!$G$102:$G$103,'Clearinghouse Official'!$G$105:$G$107,'Clearinghouse Official'!$G$110,'Clearinghouse Official'!$G$114,'Clearinghouse Official'!$G$115,'Clearinghouse Official'!$G$117:$G$120,'Clearinghouse Official'!$G$122,'Clearinghouse Official'!$G$127:$G$129,'Clearinghouse Official'!$G$134,'Clearinghouse Official'!$G$135:$G$136,'Clearinghouse Official'!$G$143,'Clearinghouse Official'!$G$168,'Clearinghouse Official'!$G$171,'Clearinghouse Official'!$G$193:$G$194,'Clearinghouse Official'!$G$198,'Clearinghouse Official'!$G$199,'Clearinghouse Official'!$G$201) -> 37804.286 | U8: =AVERAGE('Clearinghouse Official'!$G$173,'Clearinghouse Official'!$G$154,'Clearinghouse Official'!#REF!,'Clearinghouse Official'!$G$70:$G$71) -> #REF! | W8: =AVERAGE($R$8:$U$8) -> #REF!
A9: incremental cost | B9: =AVERAGE('Clearinghouse Official'!$G$6:$G$8) -> 300000 | C9: =AVERAGE('Clearinghouse Official'!$G$18,'Clearinghouse Official'!$G$24) -> 75000.5 | E9: per district | F9: =AVERAGE('Clearinghouse Official'!$G$167,'Clearinghouse Official'!$G$161) -> 5000 | G9: =AVERAGE('Clearinghouse Official'!G$180,'Clearinghouse Official'!G$177) -> 75000 | I9: Infrastructure | K9: =AVERAGE('Clearinghouse Official'!$G$191,'Clearinghouse Official'!$G$186) -> 2350 | N9: Infrastructure | O9: =AVERAGE($J$18,$J$43,$J$56) -> 107500.4 | Q9: Charger + infrastructure | S9: =AVERAGE('Clearinghouse Official'!$G$131,'Clearinghouse Official'!#REF!,'Clearinghouse Official'!$G$155:$G$156,'Clearinghouse Official'!$G$158:$G$159,'Clearinghouse Official'!#REF!,'Clearinghouse Official'!$G$162:$G$163,'Clearinghouse Official'!$G$174,'Clearinghouse Official'!$G$180) -> #REF! | T9: =AVERAGE('Clearinghouse Official'!$G$146,'Clearinghouse Official'!$G$149:$G$150,'Clearinghouse Official'!$G$152:$G$153,'Clearinghouse Official'!$G$157,'Clearinghouse Official'!$G$160:$G$161,'Clearinghouse Official'!$G$165,'Clearinghouse Official'!$G$167,'Clearinghouse Official'!$G$177,'Clearinghouse Official'!$G$179) -> 11445.545 | V9: ='Clearinghouse Official'!$G$108 -> 80000 | W9: =AVERAGE($S$9:$T$9,V9) -> #REF!
A10: per applicant | B10: =AVERAGE('Clearinghouse Official'!$G$38:$G$41,'Clearinghouse Official'!$G$42,'Clearinghouse Official'!$G$43:$G$45,'Clearinghouse Official'!$G$47:$G$48,'Clearinghouse Official'!$G$50:$G$50,'Clearinghouse Official'!$G$29) -> 620850.15 | C10: =AVERAGE('Clearinghouse Official'!$G$36,'Clearinghouse Official'!$G$30:$G$33) -> 160000.36 | E10: per port | F10: =AVERAGE('Clearinghouse Official'!$G$191,'Clearinghouse Official'!$G$195:$G$196) -> 24500 | I10: Workforce Training | J10: ='Clearinghouse Official'!$G$196 -> 70000 | Q10: Infrastructure | T10: ='Clearinghouse Official'!$G$83 -> 215000 | V10: =AVERAGE('Clearinghouse Official'!$G$132,'Clearinghouse Official'!$G$178) -> 0.8 | W10: =AVERAGE($T$10,V10) -> 107500.4
A11: per bus | B11: =AVERAGE('Clearinghouse Official'!$G$72,'Clearinghouse Official'!$G$74,'Clearinghouse Official'!$G$80:$G$83,'Clearinghouse Official'!$G$86,'Clearinghouse Official'!$G$88:$G$92,'Clearinghouse Official'!$G$96:$G$102,'Clearinghouse Official'!$G$109,'Clearinghouse Official'!$G$113) -> 72710.913 | C11: =AVERAGE('Clearinghouse Official'!$G$64,'Clearinghouse Official'!$G$73,'Clearinghouse Official'!$G$77,'Clearinghouse Official'!$G$78) -> 0.675 | N11: Other | O11: =AVERAGE($J$50:$J$52) -> #REF! | Q11: AVERAGE FUNDER | R11: =AVERAGE(R8,R6) -> 5000.25 | S11: =AVERAGE($S$5:$S$9) -> #REF! | T11: =AVERAGE($T$6:$T$10) -> #REF! | U11: =AVERAGE($U$6:$U$8) -> #REF! | V11: =AVERAGE($V$5:$V$6,V9:V10) -> #REF!
A12: per district | B12: =AVERAGE('Clearinghouse Official'!G130,'Clearinghouse Official'!#REF!,'Clearinghouse Official'!G165) -> #REF! | C12: =AVERAGE('Clearinghouse Official'!#REF!,'Clearinghouse Official'!$G$116) -> #REF! | E12: Any public fleet vehicle | F12: =AVERAGE($F$13:$F$16) -> #DIV/0! | G12: =$G$14 -> 10000 | I12: Any public fleet vehicle | J12: =AVERAGE($J$13:$J$18) -> 113166.88 | K12: =$K$13 -> N/A | N12: Resilience investments | O12: =$J$54 -> Varies
E13: incremental cost | F13: =AVERAGE('Clearinghouse Official'!$G$6) -> #DIV/0! | I13: Anything | K13: ='Clearinghouse Official'!$G$6 -> N/A | N13: Economic development investments | O13: =$J$23 -> 26525000 | R13: Any fleet vehicles | S13: Any public fleet vehicle | T13: Economic development investments | U13: Energy | V13: ESBs only | W13: EVs | X13: MDHV vehicles only | Y13: Other | Z13: Resilience investments | AA13: AVERAGE TECH
E14: per applicant | F14: =AVERAGE('Clearinghouse Official'!$G38,'Clearinghouse Official'!$G79) -> 0.75 | G14: ='Clearinghouse Official'!$G$10 -> 10000 | I14: Bus (&/or Battery) | J14: =AVERAGE('Clearinghouse Official'!$G$98,'Clearinghouse Official'!$G$79,'Clearinghouse Official'!$G$38,'Clearinghouse Official'!$G$10) -> 5833.5833 | N14: Energy | O14: =AVERAGE($J$26:$J$29) -> #REF! | Q14: Anything | T14: 26462500 | U14: 2127500 | Y14: =AVERAGE('Clearinghouse Official'!$G$16,'Clearinghouse Official'!$G$19) -> 10150000 | AA14: =AVERAGE(T14:U14,Y14) -> 12913333
A15: Bus + Charger | B15: =AVERAGE(B16:B18) -> #DIV/0! | C15: =C16 -> 25000000 | E15: per bus | F15: =AVERAGE('Clearinghouse Official'!$G98,'Clearinghouse Official'!$G109) -> 8750 | I15: Bus + Charger | J15: ='Clearinghouse Official'!$G$109 -> 10000 | N15: EVs | O15: =AVERAGE($J$39:$J$43) -> #REF! | Q15: Bus (&/or Battery) | R15: 858750 | S15: 31250 | U15: 500000 | V15: =AVERAGE('Clearinghouse Official'!$G$123,'Clearinghouse Official'!$G$111,'Clearinghouse Official'!$G$100:$G$101,'Clearinghouse Official'!$G$91,'Clearinghouse Official'!$G$74,'Clearinghouse Official'!$G$72,'Clearinghouse Official'!$G$37) -> 203000.12 | W15: =AVERAGE('Clearinghouse Official'!$G$92:$G$93,'Clearinghouse Official'!$G$89:$G$90,'Clearinghouse Official'!#REF!,'Clearinghouse Official'!$G$87) -> #REF! | X15: =AVERAGE('Clearinghouse Official'!$G$130,'Clearinghouse Official'!$G$99,'Clearinghouse Official'!$G$96:$G$97,'Clearinghouse Official'!$G$86,'Clearinghouse Official'!$G$80,'Clearinghouse Official'!$G$50:$G$50,'Clearinghouse Official'!$G$48,'Clearinghouse Official'!$G$43:$G$45,'Clearinghouse Official'!$G$47) -> 528716.75 | Y15: =AVERAGE('Clearinghouse Official'!$G$42,'Clearinghouse Official'!#REF!) -> #REF! | AA15: =AVERAGE(R15:S15,U15:V15,W15:Y15) -> #REF!
A16: per applicant | B16: =AVERAGE('Clearinghouse Official'!$G$55,'Clearinghouse Official'!$G$49) -> #DIV/0! | C16: ='Clearinghouse Official'!$G$27 -> 25000000 | E16: per district | F16: =AVERAGE('Clearinghouse Official'!$G174,'Clearinghouse Official'!$G178,'Clearinghouse Official'!$G154) -> 183333.6 | I16: Charger | J16: ='Clearinghouse Official'!$G$154 -> 50000 | N16: Any public fleet vehicle | O16: =AVERAGE($J$13:$J$18) -> 113166.88 | Q16: Bus + Charger | R16: 12000 | S16: 120000 | U16: 55000 | W16: ='Clearinghouse Official'!$G$55 -> N/A | X16: ='Clearinghouse Official'!$G$104 -> 375000 | AA16: =AVERAGE(R16:S16,U16,W16:X16) -> 140500
A17: per bus | B17: ='Clearinghouse Official'!$G$104 -> 375000 | I17: Charger + infrastructure | J17: ='Clearinghouse Official'!$G$174 -> 500000 | N17: Any fleet vehicles | O17: =AVERAGE($J$5:$J$8,$J$10) -> #REF! | Q17: Charger | R17: 11745.833 | S17: 50000 | U17: 1000000 | V17: ='Clearinghouse Official'!$G$143 -> 120000 | W17: =AVERAGE('Clearinghouse Official'!$G$143,'Clearinghouse Official'!$G$138:$G$139,'Clearinghouse Official'!$G$127:$G$127,'Clearinghouse Official'!$G$126,'Clearinghouse Official'!$G$122:$G$123,'Clearinghouse Official'!$G$119,'Clearinghouse Official'!$G$117,'Clearinghouse Official'!$G$112,'Clearinghouse Official'!$G$110,'Clearinghouse Official'!$G$107,'Clearinghouse Official'!$G$105,'Clearinghouse Official'!$G$103,'Clearinghouse Official'!$G$95,'Clearinghouse Official'!$G$93,'Clearinghouse Official'!$G$92,'Clearinghouse Official'!$G$89,'Clearinghouse Official'!#REF!,'Clearinghouse Official'!$G$88,'Clearinghouse Official'!#REF!,'Clearinghouse Official'!$G$87,'Clearinghouse Official'!$G$85,'Clearinghouse Official'!$G$81:$G$84,'Clearinghouse Official'!$G$79,'Clearinghouse Official'!$G$76,'Clearinghouse Official'!$G$71,'Clearinghouse Official'!$G$70,'Clearinghouse Official'!$G$69,'Clearinghouse Official'!$G$67,'Clearinghouse Official'!$G$63,'Clearinghouse Official'!$G$53,'Clearinghouse Official'!$G$52) -> #REF! | AA17: =AVERAGE(R17:S17,U17:W17) -> #REF!
A18: per district | B18: =AVERAGE('Clearinghouse Official'!$G$174,'Clearinghouse Official'!$G$170) -> 275000 | E18: Disaster recovery investments | G18: =$G$19 -> #REF! | I18: Infrastructure | J18: ='Clearinghouse Official'!G178 -> 0.8 | N18: MDHV vehicles only | O18: =AVERAGE($J$46:$J$47) -> 451858.38 | Q18: Charger + infrastructure | R18: 31055.556 | S18: 500000 | V18: ='Clearinghouse Official'!$G$165 -> 1 | W18: =AVERAGE('Clearinghouse Official'!#REF!,'Clearinghouse Official'!$G$155:$G$160,'Clearinghouse Official'!#REF!,'Clearinghouse Official'!$G$162:$G$163,'Clearinghouse Official'!$G$179) -> #REF! | Y18: ='Clearinghouse Official'!$G$108 -> 80000 | Z18: ='Clearinghouse Official'!$G$132 -> Varies | AA18: =AVERAGE(R18:S18,V18:W18,Y18:Z18) -> #REF!
E19: per applicant | G19: =AVERAGE('Clearinghouse Official'!#REF!,'Clearinghouse Official'!$G$169) -> #REF! | N19: ESBs only | O19: =AVERAGE($J$35:$J$36,$J$33) -> 107667.04 | Q19: Infrastructure | S19: 25000000 | W19: ='Clearinghouse Official'!$G$83 -> 215000 | AA19: =AVERAGE(S19,W19) -> 12607500
A20: Charger | B20: =AVERAGE(B21:B24) -> #REF! | C20: =AVERAGE(C21:C24) -> #REF! | I20: Disaster recovery investments | Q20: AVERAGE SECTOR | R20: =AVERAGE(R15:R18) -> 228387.85 | S20: =AVERAGE(S15:S19) -> 5140250 | T20: =T14 -> 26462500 | U20: =AVERAGE(U14:U17) -> 920625 | V20: =AVERAGE(V15,V17:V18) -> 107667.04 | W20: =AVERAGE(W15:W19) -> #REF! | X20: =AVERAGE(X15:X16) -> 451858.38 | Y20: =AVERAGE(Y14:Y15,Y18) -> #REF! | Z20: =Z18 -> Varies
A21: per applicant | B21: =AVERAGE('Clearinghouse Official'!G$58,'Clearinghouse Official'!G$63,'Clearinghouse Official'!G$66:G$67,'Clearinghouse Official'!G$70:G$71,'Clearinghouse Official'!G$56,'Clearinghouse Official'!G$57,'Clearinghouse Official'!G$59,'Clearinghouse Official'!G$61:G$62,'Clearinghouse Official'!G$71) -> 37325.25 | C21: =AVERAGE('Clearinghouse Official'!$G$53,'Clearinghouse Official'!$G$69,'Clearinghouse Official'!#REF!) -> #REF! | E21: Economic development investments | F21: =$F$22 -> 26525000 | I21: Infrastructure | K21: =AVERAGE('Clearinghouse Official'!$G$169:$G$169) -> 0.9 | N21: City | O21: =J59 -> 5000.25
A22: per charger | B22: =AVERAGE('Clearinghouse Official'!G$84,'Clearinghouse Official'!G$85,'Clearinghouse Official'!G$87:G$90,'Clearinghouse Official'!G$92:G$95,'Clearinghouse Official'!G$103,'Clearinghouse Official'!G$107,'Clearinghouse Official'!G$110,'Clearinghouse Official'!G$114:G$115,'Clearinghouse Official'!G$117:G$120,'Clearinghouse Official'!G$122,'Clearinghouse Official'!G$106,'Clearinghouse Official'!#REF!,'Clearinghouse Official'!G$128,'Clearinghouse Official'!G$129,'Clearinghouse Official'!G$133:G$134,'Clearinghouse Official'!G$135:G$138,'Clearinghouse Official'!G$141,'Clearinghouse Official'!#REF!,'Clearinghouse Official'!G$146,'Clearinghouse Official'!G$149:G$150) -> #REF! | C22: =AVERAGE('Clearinghouse Official'!$G$111,'Clearinghouse Official'!$G$151) -> 45000.25 | E22: per applicant | F22: =AVERAGE('Clearinghouse Official'!$G$14:$G$15,'Clearinghouse Official'!$G$12,'Clearinghouse Official'!$G$11) -> 26525000 | I22: Economic development investments | J22: =$J$23 -> 26525000 | N22: Federal | O22: =J63 -> #REF! | R22: incremental cost | S22: per applicant | T22: per bus | U22: per district | V22: per charger | W22: per port | X22: AVERAGE TECH
A23: per district | B23: =AVERAGE('Clearinghouse Official'!$G$154,'Clearinghouse Official'!$G$161,'Clearinghouse Official'!$G$167,'Clearinghouse Official'!$G$168,'Clearinghouse Official'!$G$171,'Clearinghouse Official'!$G$173) -> 19583.333 | C23: =AVERAGE('Clearinghouse Official'!$G$172,'Clearinghouse Official'!#REF!) -> #REF! | I23: Anything | J23: =AVERAGE('Clearinghouse Official'!$G12,'Clearinghouse Official'!$G11,'Clearinghouse Official'!$G14,'Clearinghouse Official'!$G15) -> 26525000 | N23: State | O23: =J69 -> #REF! | Q23: Anything | S23: 10385000 | U23: ='Clearinghouse Official'!$G$131 -> 1000000 | X23: =AVERAGE(S23,$U$23) -> 5692500.1
A24: per port | B24: =AVERAGE('Clearinghouse Official'!#REF!,'Clearinghouse Official'!$G$191,'Clearinghouse Official'!$G$193:$G$196,'Clearinghouse Official'!$G$198,'Clearinghouse Official'!$G$199,'Clearinghouse Official'!$G$201) -> #REF! | C24: =AVERAGE('Clearinghouse Official'!$G$192) -> 2000 | E24: Energy | F24: =AVERAGE(F25:$F$26) -> #REF! | G24: =AVERAGE($G25:G$26) -> #REF! | N24: Utility | O24: =J77 -> #REF! | Q24: Bus (&/or Battery) | R24: =AVERAGE('Clearinghouse Official'!$G$6:$G$8) -> 300000 | S24: =AVERAGE('Clearinghouse Official'!$G$38:$G$41,'Clearinghouse Official'!$G$42,'Clearinghouse Official'!$G$43:$G$45,'Clearinghouse Official'!$G$47:$G$48,'Clearinghouse Official'!$G$50:$G$50,'Clearinghouse Official'!$G$29) -> 620850.15 | T24: 81334.783 | U24: 675000 | X24: =AVERAGE($R$24:$U$24) -> 419296.23
E25: per applicant | F25: =AVERAGE('Clearinghouse Official'!$G$13,'Clearinghouse Official'!$G$17,'Clearinghouse Official'!$G$23,'Clearinghouse Official'!$G$41,'Clearinghouse Official'!#REF!) -> #REF! | G25: =AVERAGE('Clearinghouse Official'!#REF!,'Clearinghouse Official'!G$131) -> #REF! | I25: Energy | J25: =AVERAGE($J$26:$J$29) -> #REF! | K25: =AVERAGE($K$26,$K$29:$K$30) -> #REF! | N25: VW Settlement | O25: =J84 -> #REF! | Q25: Bus + Charger | S25: 8500 | T25: 375000 | U25: 87500 | X25: =AVERAGE($S$25:$U$25) -> 157000
A26: Charger + infrastructure | B26: =AVERAGE(B27:B29) -> #REF! | C26: =AVERAGE(C27:C29) -> #REF! | E26: per district | F26: =AVERAGE('Clearinghouse Official'!$G170,'Clearinghouse Official'!$G144) -> 25000.5 | G26: ='Clearinghouse Official'!$G$175 -> 1 | I26: Anything | J26: =AVERAGE('Clearinghouse Official'!$G$23,'Clearinghouse Official'!#REF!,'Clearinghouse Official'!$G$13,'Clearinghouse Official'!$G$9) -> #REF! | K26: ='Clearinghouse Official'!#REF! -> #REF! | Q26: Charger | S26: 19650 | U26: 34208.333 | V26: 4833.3307 | W26: =AVERAGE('Clearinghouse Official'!#REF!,'Clearinghouse Official'!$G$191,'Clearinghouse Official'!$G$193:$G$196,'Clearinghouse Official'!$G$198,'Clearinghouse Official'!$G$199,'Clearinghouse Official'!$G$201) -> #REF! | X26: =AVERAGE($S$26,$U$26:$W$26) -> #REF!
A27: per applicant | B27: =AVERAGE('Clearinghouse Official'!$G$82,'Clearinghouse Official'!$G$84:$G$85,'Clearinghouse Official'!$G$105,'Clearinghouse Official'!$G$108,'Clearinghouse Official'!$G$112,'Clearinghouse Official'!$G$121,'Clearinghouse Official'!#REF!,'Clearinghouse Official'!$G$126) -> #REF! | C27: =AVERAGE('Clearinghouse Official'!$G$65,'Clearinghouse Official'!$G$75,'Clearinghouse Official'!$G$76) -> 0.65 | I27: Bus (&/or Battery) | J27: ='Clearinghouse Official'!$G$41 -> 500000 | Q27: Charger + infrastructure | S27: 189444 | U27: 500000 | V27: 13654 | X27: =AVERAGE($U$27:$V$27,$S$27) -> 234366
A28: per charger | B28: =AVERAGE('Clearinghouse Official'!#REF!,'Clearinghouse Official'!#REF!,'Clearinghouse Official'!$G$152:$G$153,'Clearinghouse Official'!$G$155,'Clearinghouse Official'!$G$156:$G$160,'Clearinghouse Official'!#REF!,'Clearinghouse Official'!$G$162:$G$163) -> #REF! | C28: =AVERAGE('Clearinghouse Official'!$G$139:$G$140,'Clearinghouse Official'!$G$142,'Clearinghouse Official'!$G$145) -> 5875.075 | E28: ESBs only | F28: =AVERAGE($F$29:$F$33) -> #REF! | G28: =AVERAGE($G$29,$G$31:$G$32) -> 12500500 | I28: Bus + Charger | J28: ='Clearinghouse Official'!$G$126 -> 150000 | Q28: Infrastructure | S28: 9005003 | X28: =S28 -> 9005003
A29: per district | B29: =AVERAGE('Clearinghouse Official'!$G$178:$G$179) -> 0.8 | C29: =AVERAGE('Clearinghouse Official'!$G$175,'Clearinghouse Official'!#REF!) -> #REF! | E29: per applicant | F29: ='Clearinghouse Official'!$G$29 -> N/A | G29: ='Clearinghouse Official'!$G$27 -> 25000000 | I29: Charger + infrastructure | J29: ='Clearinghouse Official'!$G$131 -> 1000000 | K29: ='Clearinghouse Official'!G144 -> 1 | Q29: AVERAGE PER UNIT | R29: =R24 -> 300000 | S29: =AVERAGE($S$23:$S$28) -> 3371407.9 | T29: =AVERAGE($T$24:$T$25) -> 228167.39 | U29: =AVERAGE($U$23:$U$27) -> 459341.67 | V29: =AVERAGE($V$26:$V$27) -> 9243.6653 | W29: =$W$26 -> #REF!
E30: per bus | F30: =AVERAGE('Clearinghouse Official'!$G72,'Clearinghouse Official'!$G74,'Clearinghouse Official'!$G91,'Clearinghouse Official'!$G100:$G101,'Clearinghouse Official'!$G111) -> 74333.475 | I30: Infrastructure | K30: ='Clearinghouse Official'!$G$175 -> 1
A31: Infrastructure | B31: =B32 -> 13630 | C31: =AVERAGE(C32:C33) -> #REF! | E31: per charger | F31: =AVERAGE('Clearinghouse Official'!$G$123) -> 975000 | G31: ='Clearinghouse Official'!$G$113 -> N/A | I31: ESBs only | J31: =AVERAGE($J$35:$J$36,$J$33) -> 107667.04 | K31: =AVERAGE($K$34:$K$35,$K$32) -> #REF! | R31: Any fleet vehicles | S31: Any public fleet vehicle | T31: Economic development investments | U31: Energy | V31: ESBs only | W31: EVs | X31: MDHV vehicles only | Y31: Other | Z31: Resilience investments | AA31: AVG. UNIT
A32: per applicant | B32: =AVERAGE('Clearinghouse Official'!$G$79,'Clearinghouse Official'!$G$127,'Clearinghouse Official'!$G$132) -> 13630 | C32: =AVERAGE('Clearinghouse Official'!#REF!,'Clearinghouse Official'!$G$169) -> #REF! | E32: per district | F32: ='Clearinghouse Official'!$G$165 -> 1 | G32: ='Clearinghouse Official'!$G$124 -> 1000 | I32: Anything | K32: ='Clearinghouse Official'!$G$27 -> 25000000 | Q32: incremental cost | R32: 125000 | S32: 10000 | AA32: =AVERAGE($R$32:$S$32) -> 67500
A33: per district | C33: =AVERAGE('Clearinghouse Official'!$G$177,'Clearinghouse Official'!$G$180:$G$183) -> 31800 | E33: per port | F33: ='Clearinghouse Official'!#REF! -> #REF! | I33: Bus (&/or Battery) | J33: =AVERAGE('Clearinghouse Official'!$G$123,'Clearinghouse Official'!$G$111,'Clearinghouse Official'!$G$100:$G$101,'Clearinghouse Official'!$G$91,'Clearinghouse Official'!$G$74,'Clearinghouse Official'!$G$72,'Clearinghouse Official'!$G$37) -> 203000.12 | Q33: per applicant | R33: 465538.51 | S33: 12550000 | T33: 26462500 | U33: 2127500 | V33: 215000 | W33: 13343.5 | X33: 1282000 | Y33: 288750 | Z33: 2000000 | AA33: =AVERAGE($R$33:$Z$33) -> 5044959.1
I34: Bus + Charger | K34: ='Clearinghouse Official'!$G$124 -> 1000 | Q34: per bus | R34: 2500 | S34: 7500 | V34: 86266.667 | W34: 5742.8571 | X34: 217000 | AA34: =AVERAGE($V$34:$X$34,$R$34:$S$34) -> 63801.905
I35: Charger | J35: ='Clearinghouse Official'!$G$143 -> 120000 | K35: ='Clearinghouse Official'!#REF! -> #REF! | Q35: per charger | R35: 9327.7778 | V35: 10000 | W35: 96966.842 | AA35: =AVERAGE($V$35:$W$35,$R$35) -> 38764.873
E36: EVs | F36: =AVERAGE(F37:$F$41) -> #REF! | G36: =AVERAGE($G$37,G39:$G$41) -> #REF! | I36: Charger + infrastructure | J36: ='Clearinghouse Official'!$G$165 -> 1 | Q36: per district | R36: 50000 | S36: 223333.33 | U36: 277500 | V36: 975000 | W36: 138812.5 | X36: 500000 | Y36: 550000 | AA36: =AVERAGE($U$36:$Y$36,$R$36:$S$36) -> 387806.55
E37: per applicant | F37: =AVERAGE('Clearinghouse Official'!$G81, 'Clearinghouse Official'!$G70:$G71,'Clearinghouse Official'!$G66:$G67,'Clearinghouse Official'!$G61:$G63,'Clearinghouse Official'!$G55:$G59,'Clearinghouse Official'!$G83) -> 73575.25 | G37: =AVERAGE('Clearinghouse Official'!$G$69:$G$69,'Clearinghouse Official'!$G$75:$G$76) -> 0.5 | Q37: per port | R37: 3833.3333 | V37: 6000 | W37: 2730 | AA37: =AVERAGE($V$37:$W$37,$R$37) -> 4187.7778
E38: per bus | F38: =AVERAGE('Clearinghouse Official'!$G$92,'Clearinghouse Official'!$G$89:$G$90,'Clearinghouse Official'!#REF!,'Clearinghouse Official'!$G$87,'Clearinghouse Official'!$G$93) -> #REF! | I38: EVs | J38: =AVERAGE($J$39:$J$43) -> #REF! | K38: =AVERAGE($K$41:$K$43,$K$39) -> #REF! | Q38: AVG. SECTOR | R38: =AVERAGE($R$32:$R$37) -> 109366.6 | S38: =AVERAGE(S36,$S$32:$S$34) -> 3197708.3 | T38: =$T$33 -> 26462500 | U38: =AVERAGE(U36,U33) -> 1202500 | V38: =AVERAGE($V$33:$V$37) -> 258453.33 | W38: =AVERAGE($W$33:$W$37) -> 51519.14 | X38: =AVERAGE(X36,$X$33:$X$34) -> 666333.33 | Y38: =AVERAGE(Y36,Y33) -> 419375 | Z38: =$Z$33 -> 2000000
E39: per charger | F39: =AVERAGE('Clearinghouse Official'!$G95,'Clearinghouse Official'!$G103,'Clearinghouse Official'!$G106:$G107,'Clearinghouse Official'!$G110,'Clearinghouse Official'!$G114:$G115,'Clearinghouse Official'!$G117:$G120,'Clearinghouse Official'!$G122,'Clearinghouse Official'!$G128:$G129,'Clearinghouse Official'!$G133,'Clearinghouse Official'!$G136:$G137,'Clearinghouse Official'!#REF!,'Clearinghouse Official'!$G155:$G160,'Clearinghouse Official'!#REF!,'Clearinghouse Official'!$G162:$G163,'Clearinghouse Official'!$G135,'Clearinghouse Official'!$G127) -> #REF! | G39: =AVERAGE('Clearinghouse Official'!$G$145,'Clearinghouse Official'!$G$142,'Clearinghouse Official'!$G$139:$G$140) -> 5875.075 | I39: Bus (&/or Battery) | J39: =AVERAGE('Clearinghouse Official'!$G$92:$G$93,'Clearinghouse Official'!$G$89:$G$90,'Clearinghouse Official'!#REF!,'Clearinghouse Official'!$G$87) -> #REF! | K39: ='Clearinghouse Official'!#REF! -> #REF!
E40: per district | F40: =AVERAGE('Clearinghouse Official'!$G$179,'Clearinghouse Official'!$G$173,'Clearinghouse Official'!$G$171,'Clearinghouse Official'!$G$168) -> 19166.667 | G40: =AVERAGE('Clearinghouse Official'!#REF!,'Clearinghouse Official'!#REF!,'Clearinghouse Official'!#REF!,'Clearinghouse Official'!$G$181:$G$183) -> #REF! | I40: Bus + Charger | J40: ='Clearinghouse Official'!$G$55 -> N/A
E41: per port | F41: =AVERAGE('Clearinghouse Official'!$G$201,'Clearinghouse Official'!$G$199,'Clearinghouse Official'!$G$198,'Clearinghouse Official'!$G$193:$G$194) -> 1600 | G41: ='Clearinghouse Official'!$G$192 -> 2000 | I41: Charger | J41: =AVERAGE('Clearinghouse Official'!$G$143,'Clearinghouse Official'!$G$138:$G$139,'Clearinghouse Official'!$G$127:$G$127,'Clearinghouse Official'!$G$126,'Clearinghouse Official'!$G$122:$G$123,'Clearinghouse Official'!$G$119,'Clearinghouse Official'!$G$117,'Clearinghouse Official'!$G$112,'Clearinghouse Official'!$G$110,'Clearinghouse Official'!$G$107,'Clearinghouse Official'!$G$105,'Clearinghouse Official'!$G$103,'Clearinghouse Official'!$G$95,'Clearinghouse Official'!$G$93,'Clearinghouse Official'!$G$92,'Clearinghouse Official'!$G$89,'Clearinghouse Official'!#REF!,'Clearinghouse Official'!$G$88,'Clearinghouse Official'!#REF!,'Clearinghouse Official'!$G$87,'Clearinghouse Official'!$G$85,'Clearinghouse Official'!$G$81:$G$84,'Clearinghouse Official'!$G$79,'Clearinghouse Official'!$G$76,'Clearinghouse Official'!$G$71,'Clearinghouse Official'!$G$70,'Clearinghouse Official'!$G$69,'Clearinghouse Official'!$G$67,'Clearinghouse Official'!$G$63,'Clearinghouse Official'!$G$53,'Clearinghouse Official'!$G$52) -> #REF! | K41: =AVERAGE('Clearinghouse Official'!$G$69:$G$69,'Clearinghouse Official'!#REF!,'Clearinghouse Official'!$G$192) -> #REF!
I42: Charger + infrastructure | J42: =AVERAGE('Clearinghouse Official'!#REF!,'Clearinghouse Official'!$G$155:$G$160,'Clearinghouse Official'!#REF!,'Clearinghouse Official'!$G$162:$G$163,'Clearinghouse Official'!$G$179) -> #REF! | K42: =AVERAGE('Clearinghouse Official'!#REF!,'Clearinghouse Official'!$G$145,'Clearinghouse Official'!$G$142,'Clearinghouse Official'!$G$139:$G$140,'Clearinghouse Official'!$G$76,'Clearinghouse Official'!$G$75) -> #REF!
...

Sheet Vizualizations 2022.12

Sheet PIVOT 2022.12
D2: Type of Program | E2: Count | G2: Type of Funder | H2: Count | J2: Eligible/Sector | K2: Count | N2: City | O2: Federal | P2: Regional jurisdiction | Q2: State | R2: Utility | S2: VW Settlement
